Workbook

Sheet Arvind & LC Invoice Details.
A1: Arvind & Linen Club Invoice Details | G1: =SUBTOTAL(9,G3:G1001) -> 6630 | H1: =SUBTOTAL(9,H3:H1001) -> 14655490 | I1: =SUBTOTAL(9,I3:I1001) -> 22369532 | J1: Invoice Count | K1: =SUBTOTAL(3,B3:B1001) -> 67
A2: Supplier Name | B2: Invoice Number | C2: Invoice Date | D2: Month | E2: Year | F2: Brand Name | G2: Quantity | H2: Billing Amount | I2: MRP Amount | J2: Invoice Soft Copy | K2: Invoice Season | L2: Invoice Status | M2: Stock Remarks | N2: Booking Status | O2: Margin Analysis Status
A3: VISHAL MARKETING & COMPANY | B3: S/25-26/842 | C3: 45875 | D3: =IF(C3=0," ",TEXT(C3,"MMMM")) -> August | E3: =IF(C3=0," ",TEXT(C3,"YYYY")) -> 2025 | F3: U.S POLO | G3: 136 | H3: 288717 | I3: 411664 | J3: VISHAL MARKETING & CO(US POLO)-842.pdf | K3: AW'25 | L3: Uploaded In TEN | M3: TAS (HZB) Stock Transfer To JainSons (HZB). | N3: BOOKED IN VENUE. | O3: DONE.
A4: VISHAL MARKETING & COMPANY | B4: S/25-26/875 | C4: 45880 | D4: =IF(C4=0," ",TEXT(C4,"MMMM")) -> August | E4: =IF(C4=0," ",TEXT(C4,"YYYY")) -> 2025 | F4: U.S POLO | G4: 277 | H4: 641394 | I4: 914523 | J4: VISHAL MARKETING & CO(US POLO)-875.pdf | K4: AW'25 | L4: Uploaded In TEN | M4: Deoghar Stock Transfer To Patna. | N4: BOOKED IN VENUE. | O4: DONE.
A5: VISHAL MARKETING & COMPANY | B5: S/25-26/890 | C5: 45880 | D5: =IF(C5=0," ",TEXT(C5,"MMMM")) -> August | E5: =IF(C5=0," ",TEXT(C5,"YYYY")) -> 2025 | F5: ARROW | G5: 193 | H5: 337736 | I5: 494507 | J5: VISHAL MARKETING & CO(ARROW)-890.pdf | K5: AW'25 | L5: Uploaded In TEN | M5: Product Received (Lee Deoghar). | N5: BOOKED IN VENUE. | O5: DONE.
A6: VISHAL MARKETING & COMPANY | B6: S/25-26/891 | C6: 45880 | D6: =IF(C6=0," ",TEXT(C6,"MMMM")) -> August | E6: =IF(C6=0," ",TEXT(C6,"YYYY")) -> 2025 | F6: ARROW | G6: 222 | H6: 384126 | I6: 563878 | J6: VISHAL MARKETING & CO(ARROW)-891.pdf | K6: AW'25 | L6: Uploaded In TEN | M6: Product Received (Lee Deoghar). | N6: BOOKED IN VENUE. | O6: DONE.
A7: VISHAL MARKETING & COMPANY | B7: S/25-26/906 | C7: 45881 | D7: =IF(C7=0," ",TEXT(C7,"MMMM")) -> August | E7: =IF(C7=0," ",TEXT(C7,"YYYY")) -> 2025 | F7: FLYING MACHINE | G7: 270 | H7: 403814 | I7: 594830 | J7: VISHAL MARKETING & CO(FM)-906.pdf | K7: AW'25 | L7: Uploaded In TEN | M7: Product Received (Vaishnavi Deoghar). | N7: BOOKED IN VENUE. | O7: DONE.
A8: VISHAL MARKETING & COMPANY | B8: S/25-26/934 | C8: 45883 | D8: =IF(C8=0," ",TEXT(C8,"MMMM")) -> August | E8: =IF(C8=0," ",TEXT(C8,"YYYY")) -> 2025 | F8: U.S POLO KIDS | G8: 114 | H8: 166997 | I8: 238486 | J8: VISHAL MARKETING & CO(USPA KIDS)-934.pdf | K8: AW'25 | L8: Uploaded In TEN | M8: Product Received (Vaishnavi Deoghar). | N8: BOOKED IN VENUE. | O8: DONE.
A9: VISHAL MARKETING & COMPANY | B9: S/25-26/949 | C9: 45885 | D9: =IF(C9=0," ",TEXT(C9,"MMMM")) -> August | E9: =IF(C9=0," ",TEXT(C9,"YYYY")) -> 2025 | F9: U.S POLO | G9: 58 | H9: 127393 | I9: 181642 | J9: VISHAL MARKETING & CO(US POLO)-949.pdf | K9: AW'25 | L9: Uploaded In TEN | M9: TAS (HZB) Stock Transfer To JainSons (HZB). | N9: BOOKED IN VENUE. | O9: DONE.
A10: VISHAL MARKETING & COMPANY | B10: S/25-26/1023 | C10: 45888 | D10: =IF(C10=0," ",TEXT(C10,"MMMM")) -> August | E10: =IF(C10=0," ",TEXT(C10,"YYYY")) -> 2025 | F10: FLYING MACHINE | G10: 21 | H10: 25495 | I10: 37079 | J10: VISHAL MARKETING & CO(FM)-1023.pdf | K10: AW'25 | L10: Uploaded In TEN | M10: Product Received (Vaishnavi Deoghar). | N10: BOOKED IN VENUE. | O10: DONE.
A11: VISHAL MARKETING & COMPANY | B11: S/25-26/1024 | C11: 45888 | D11: =IF(C11=0," ",TEXT(C11,"MMMM")) -> August | E11: =IF(C11=0," ",TEXT(C11,"YYYY")) -> 2025 | F11: ARROW | G11: 68 | H11: 99668 | I11: 145932 | J11: VISHAL MARKETING & CO(ARROW)-1024.pdf | K11: AW'25 | L11: Uploaded In TEN | M11: Product Received (Lee Deoghar). | N11: BOOKED IN VENUE. | O11: DONE.
A12: VISHAL MARKETING & COMPANY | B12: S/25-26/999 | C12: 45888 | D12: =IF(C12=0," ",TEXT(C12,"MMMM")) -> August | E12: =IF(C12=0," ",TEXT(C12,"YYYY")) -> 2025 | F12: U.S POLO | G12: 127 | H12: 299595 | I12: 427173 | J12: VISHAL MARKETING & CO(US POLO)-999.pdf | K12: AW'25 | L12: Uploaded In TEN | M12: Deoghar Stock Transfer To Patna. | N12: BOOKED IN VENUE. | O12: DONE.
A13: VISHAL MARKETING & COMPANY | B13: S/25-26/1125 | C13: 45894 | D13: =IF(C13=0," ",TEXT(C13,"MMMM")) -> August | E13: =IF(C13=0," ",TEXT(C13,"YYYY")) -> 2025 | F13: U.S POLO | G13: 100 | H13: 235862 | I13: 336300 | J13: VISHAL MARKETING & CO(US POLO)-1125.pdf | K13: AW'25 | L13: Uploaded In TEN | M13: Product Received (Lee Deoghar). | N13: BOOKED IN "DB". | O13: PENDING.
A14: VISHAL MARKETING & COMPANY | B14: S/25-26/1126 | C14: 45894 | D14: =IF(C14=0," ",TEXT(C14,"MMMM")) -> August | E14: =IF(C14=0," ",TEXT(C14,"YYYY")) -> 2025 | F14: U.S POLO | G14: 125 | H14: 266072 | I14: 379375 | J14: VISHAL MARKETING & CO(US POLO)-1126.pdf | K14: AW'25 | L14: Uploaded In TEN | M14: Product Received (Lee Deoghar). | N14: BOOKED IN "DB". | O14: PENDING.
... A41: VISHAL MARKETING & COMPANY | B41: S/25-26/1577 | C41: 45925 | D41: =IF(C41=0," ",TEXT(C41,"MMMM")) -> September | E41: =IF(C41=0," ",TEXT(C41,"YYYY")) -> 2025 | F41: U.S POLO | G41: 131 | H41: 273563 | I41: 428940 | J41: VISHAL MARKETING & CO(US POLO)-1577.pdf | K41: AW'25 | L41: Uploaded In TEN | M41: Stock Transfered 66 Units Lee Deoghar, 28 Units USPA & SPYKAR, & 37 Units Allen Solly Gaya. | N41: BOOKED IN VENUE. | O41: PENDING.
A42: VISHAL MARKETING & COMPANY | B42: S/25-26/2122 | C42: 45954 | D42: =IF(C42=0," ",TEXT(C42,"MMMM")) -> October | E42: =IF(C42=0," ",TEXT(C42,"YYYY")) -> 2025 | F42: ARROW | G42: 78 | H42: 331393 | I42: 504793 | J42: VISHAL MARKETING & CO(ARROW)-2122.pdf | K42: AW'25 | L42: Uploaded In TEN | N42: BOOKED IN VENUE. | O42: PENDING.
A43: VISHAL MARKETING & COMPANY | B43: S/25-26/2142 | C43: 45955 | D43: =IF(C43=0," ",TEXT(C43,"MMMM")) -> October | E43: =IF(C43=0," ",TEXT(C43,"YYYY")) -> 2025 | F43: ARROW | G43: 17 | H43: 75849 | I43: 113768 | J43: VISHAL MARKETING & CO(ARROW)-2142.pdf | K43: AW'25 | L43: Uploaded In TEN | N43: BOOKED IN VENUE. | O43: PENDING.
A44: VISHAL MARKETING & COMPANY | B44: S/25-26/2329 | C44: 45788 | D44: =IF(C44=0," ",TEXT(C44,"MMMM")) -> May | E44: =IF(C44=0," ",TEXT(C44,"YYYY")) -> 2025 | F44: ARROW | G44: 53 | H44: 175689 | I44: 268394 | J44: VISHAL MARKETING & CO(ARROW)-2329.pdf | K44: AW'25 | L44: Uploaded In TEN | N44: BOOKED IN VENUE. | O44: PENDING.
A45: VISHAL MARKETING & COMPANY | B45: S/25-26/2453 | C45: 45972 | D45: =IF(C45=0," ",TEXT(C45,"MMMM")) -> November | E45: =IF(C45=0," ",TEXT(C45,"YYYY")) -> 2025 | F45: ARROW | G45: 105 | H45: 321032 | I45: 496227 | J45: VISHAL MARKETING & CO(ARROW)-2453.pdf | K45: AW'25 | L45: Uploaded In TEN | N45: BOOKED IN VENUE. | O45: PENDING.
A46: VISHAL MARKETING & COMPANY | B46: S/25-26/2622 | C46: 45982 | D46: =IF(C46=0," ",TEXT(C46,"MMMM")) -> November | E46: =IF(C46=0," ",TEXT(C46,"YYYY")) -> 2025 | F46: ARROW | G46: 92 | H46: 418516 | I46: 630993 | J46: VISHAL MARKETING & CO(ARROW)-2622.pdf | K46: AW'25 | L46: Uploaded In TEN | N46: BOOKED IN VENUE. | O46: PENDING.
A47: VISHAL MARKETING & COMPANY | B47: S/25-26/2145 | C47: 45955 | D47: =IF(C47=0," ",TEXT(C47,"MMMM")) -> October | E47: =IF(C47=0," ",TEXT(C47,"YYYY")) -> 2025 | F47: FLYING MACHINE | G47: 27 | H47: 49713 | I47: 75410 | J47: VISHAL MARKETING & CO(FM)-2145.pdf | K47: AW'25 | L47: Uploaded In TEN | M47: Product Received (Vaishnavi Deoghar). | N47: BOOKED IN VENUE. | O47: PENDING.
A48: VISHAL MARKETING & COMPANY | B48: S/25-26/2480 | C48: 45973 | D48: =IF(C48=0," ",TEXT(C48,"MMMM")) -> November | E48: =IF(C48=0," ",TEXT(C48,"YYYY")) -> 2025 | F48: FLYING MACHINE | G48: 21 | H48: 86759 | I48: 129778 | J48: VISHAL MARKETING & CO(FM)-2480.pdf | K48: AW'25 | L48: Uploaded In TEN | M48: Product Received (Vaishnavi Deoghar). | N48: BOOKED IN VENUE. | O48: PENDING.
A49: VISHAL MARKETING & COMPANY | B49: S/25-26/1578 | C49: 45925 | D49: =IF(C49=0," ",TEXT(C49,"MMMM")) -> September | E49: =IF(C49=0," ",TEXT(C49,"YYYY")) -> 2025 | F49: U.S POLO | G49: 79 | H49: 164885 | I49: 253053 | J49: VISHAL MARKETING & CO(US POLO)-1578.pdf | K49: AW'25 | L49: Uploaded In TEN | M49: Product Received (Vaishnavi Deoghar). | N49: BOOKED IN VENUE. | O49: PENDING.
A50: VISHAL MARKETING & COMPANY | B50: S/25-26/1579 | C50: 45925 | D50: =IF(C50=0," ",TEXT(C50,"MMMM")) -> September | E50: =IF(C50=0," ",TEXT(C50,"YYYY")) -> 2025 | F50: U.S POLO | G50: 94 | H50: 203236 | I50: 320182 | J50: VISHAL MARKETING & CO(US POLO)-1579.pdf | K50: AW'25 | L50: Uploaded In TEN | M50: Product Received (Vaishnavi Deoghar). | N50: BOOKED IN VENUE. | O50: PENDING.
A51: VISHAL MARKETING & COMPANY | B51: S/25-26/1786 | C51: 45818 | D51: =IF(C51=0," ",TEXT(C51,"MMMM")) -> June | E51: =IF(C51=0," ",TEXT(C51,"YYYY")) -> 2025 | F51: U.S POLO | G51: 21 | H51: 41043 | I51: 67301 | J51: VISHAL MARKETING & CO(US POLO)-1786.pdf | K51: AW'25 | L51: Uploaded In TEN | M51: Product Received (Vaishnavi Deoghar). | N51: BOOKED IN VENUE. | O51: PENDING.
A52: VISHAL MARKETING & COMPANY | B52: S/25-26/2068 | C52: 45948 | D52: =IF(C52=0," ",TEXT(C52,"MMMM")) -> October | E52: =IF(C52=0," ",TEXT(C52,"YYYY")) -> 2025 | F52: U.S POLO | G52: 38 | H52: 90981 | I52: 139434 | J52: VISHAL MARKETING & CO(US POLO)-2068.pdf | K52: AW'25 | L52: Uploaded In TEN | M52: Product Received (Vaishnavi Deoghar). | N52: BOOKED IN VENUE. | O52: PENDING.
A53: VISHAL MARKETING & COMPANY | B53: S/25-26/2070 | C53: 45948 | D53: =IF(C53=0," ",TEXT(C53,"MMMM")) -> October | E53: =IF(C53=0," ",TEXT(C53,"YYYY")) -> 2025 | F53: U.S POLO | G53: 22 | H53: 55308 | I53: 86600 | J53: VISHAL MARKETING & CO(US POLO)-2070.pdf | K53: AW'25 | L53: Uploaded In TEN | M53: Product Received (Vaishnavi Deoghar). | N53: BOOKED IN VENUE. | O53: PENDING.
A54: VISHAL MARKETING & COMPANY | B54: S/25-26/2090 | C54: 45948 | D54: =IF(C54=0," ",TEXT(C54,"MMMM")) -> October | E54: =IF(C54=0," ",TEXT(C54,"YYYY")) -> 2025 | F54: U.S POLO | G54: 82 | H54: 315698 | I54: 469764 | J54: VISHAL MARKETING & CO(US POLO)-2090.pdf | K54: AW'25 | L54: Uploaded In TEN | M54: Product Received (Vaishnavi Deoghar). | N54: BOOKED IN VENUE. | O54: PENDING.
A55: VISHAL MARKETING & COMPANY | B55: S/25-26/2144 | C55: 45955 | D55: =IF(C55=0," ",TEXT(C55,"MMMM")) -> October | E55: =IF(C55=0," ",TEXT(C55,"YYYY")) -> 2025 | F55: U.S POLO | G55: 14 | H55: 26359 | I55: 43223 | J55: VISHAL MARKETING & CO(US POLO)-2144.pdf | K55: AW'25 | L55: Uploaded In TEN | M55: Product Received (Vaishnavi Deoghar). | N55: BOOKED IN VENUE. | O55: PENDING.
A56: VISHAL MARKETING & COMPANY | B56: S/25-26/2263 | C56: 45668 | D56: =IF(C56=0," ",TEXT(C56,"MMMM")) -> January | E56: =IF(C56=0," ",TEXT(C56,"YYYY")) -> 2025 | F56: U.S POLO | G56: 151 | H56: 390079 | I56: 617444 | J56: VISHAL MARKETING & CO(US POLO)-2263.pdf | K56: AW'25 | L56: Uploaded In TEN | M56: Product Received (Vaishnavi Deoghar). | N56: BOOKED IN VENUE. | O56: PENDING.
A57: VISHAL MARKETING & COMPANY | B57: S/25-26/2264 | C57: 45668 | D57: =IF(C57=0," ",TEXT(C57,"MMMM")) -> January | E57: =IF(C57=0," ",TEXT(C57,"YYYY")) -> 2025 | F57: U.S POLO | G57: 103 | H57: 220372 | I57: 350293 | J57: VISHAL MARKETING & CO(US POLO)-2264.pdf | K57: AW'25 | L57: Uploaded In TEN | M57: Product Received (Vaishnavi Deoghar). | N57: BOOKED IN VENUE. | O57: PENDING.
A58: VISHAL MARKETING & COMPANY | B58: S/25-26/2284 | C58: 45668 | D58: =IF(C58=0," ",TEXT(C58,"MMMM")) -> January | E58: =IF(C58=0," ",TEXT(C58,"YYYY")) -> 2025 | F58: U.S POLO | G58: 33 | H58: 68625 | I58: 111121 | J58: VISHAL MARKETING & CO(US POLO)-2284.pdf | K58: AW'25 | L58: Uploaded In TEN | M58: Product Received (Vaishnavi Deoghar). | N58: BOOKED IN VENUE. | O58: PENDING.
... A69: VISHAL MARKETING & COMPANY | B69: S/302 | C69: 45980 | D69: =IF(C69=0," ",TEXT(C69,"MMMM")) -> November | E69: =IF(C69=0," ",TEXT(C69,"YYYY")) -> 2025 | F69: LINEN CLUB | G69: 21 | H69: 48327 | I69: 81102 | J69: VISHAL MARKETING & CO(LINEN CLUB)-302.pdf | K69: AW'25 | L69: Uploaded In TEN | M69: Product Received at Ranchi(WH), Stock Transfered 03 Units Vaishnavi Banka, 06 Units Vaishnavi Ratu, & 21 Units KDPS Bokaro. | N69: BOOKED IN VENUE. | O69: PENDING.
D70: =IF(C70=0," ",TEXT(C70,"MMMM")) | E70: =IF(C70=0," ",TEXT(C70,"YYYY"))
D71: =IF(C71=0," ",TEXT(C71,"MMMM")) | E71: =IF(C71=0," ",TEXT(C71,"YYYY"))
D72: =IF(C72=0," ",TEXT(C72,"MMMM")) | E72: =IF(C72=0," ",TEXT(C72,"YYYY"))
D73: =IF(C73=0," ",TEXT(C73,"MMMM")) | E73: =IF(C73=0," ",TEXT(C73,"YYYY"))
D74: =IF(C74=0," ",TEXT(C74,"MMMM")) | E74: =IF(C74=0," ",TEXT(C74,"YYYY"))
D75: =IF(C75=0," ",TEXT(C75,"MMMM")) | E75: =IF(C75=0," ",TEXT(C75,"YYYY"))
D76: =IF(C76=0," ",TEXT(C76,"MMMM")) | E76: =IF(C76=0," ",TEXT(C76,"YYYY"))
...

Sheet OFFER DETAILS.
A1: Brand Name | B1: Offer Type | C1: Season | D1: Offer Details | E1: Offer Starting Date | F1: Offer Closing Date | G1: Offer Status | H1: Offer Artwork
A2: U. S. POLO | B2: GWP | C2: AW'25 | D2: BUY 7999/- & GET A DUFFEL BAG WORTH 4999/- FOR 499/- | E2: 45906 | F2: 45940 | G2: CLOSED | H2: US POLO AW'25 GWP OFFER ARTWORK.pdf
A3: U. S. POLO | B3: GWP | C3: AW'25 | D3: BUY 10999/- & GET A BACKPACK WORTH 6999/- FOR 699/- | E3: 45906 | F3: 45940 | G3: CLOSED
A4: U. S. POLO | B4: GWP | C4: AW'25 | D4: BUY 16999/- & GET A TROLLEY WORTH 7999/- FOR 799/- | E4: 45906 | F4: 45940 | G4: CLOSED
A5: U. S. POLO KIDS | B5: GWP | C5: AW'25 | D5: BUY 5999/- & GET A SCHOOL BAG WORTH 3995/- FOR 499/- | E5: 45906 | F5: 45940 | G5: CLOSED | H5: US POLO KIDS AW'25 GWP OFFER ARTWORK.pdf
A6: U. S. POLO KIDS | B6: GWP | C6: AW'25 | D6: BUY 7999/- & GET A SCHOOL BAG + TIFFIN CASE WORTH 4995/- FOR 699/- | E6: 45906 | F6: 45940 | G6: CLOSED
A7: U. S. POLO KIDS | B7: GWP | C7: AW'25 | D7: BUY 10999/- & GET A TROLLY WORTH 7995/- FOR 799/- | E7: 45906 | F7: 45940 | G7: CLOSED
A8: FLYING MACHINE | B8: ATV | C8: AW'25 | D8: BUY 14999/- GET 3000/- 0FF | E8: 45908 | F8: 45961 | G8: CLOSED | H8: FM ATV OFFER AW'25 ARTWORK.pdf
A9: FLYING MACHINE | B9: ATV | C9: AW'25 | D9: BUY 10999/- GET 2000/- 0FF | E9: 45908 | F9: 45961 | G9: CLOSED
A10: FLYING MACHINE | B10: ATV | C10: AW'25 | D10: BUY 5999/- GET 1000/- 0FF | E10: 45908 | F10: 45961 | G10: CLOSED
A11: ARROW | B11: ATV | C11: AW'25 | D11: BUY 16999/- GET 3000/- 0FF | E11: 45908 | F11: 45961 | G11: CLOSED | H11: ARROW ATV OFFER AW'25 ARTWORK.pdf
A12: ARROW | B12: ATV | C12: AW'25 | D12: BUY 12999/- GET 2000/- 0FF | E12: 45908 | F12: 45961 | G12: CLOSED
A13: ARROW | B13: ATV | C13: AW'25 | D13: BUY 6999/- GET 1000/- 0FF | E13: 45908 | F13: 45961 | G13: CLOSED
A14: LINEN CLUB | B14: ATV | C14: AW'25 | D14: BUY 2 GET 750/- OFF | E14: 45903 | F14: 46134 | G14: CLOSED | H14: LINEN CLUB ATV OFFER AW'25 ARTWORK.pdf
A15: LINEN CLUB | B15: ATV | C15: AW'25 | D15: BUY 3 GET 1250/- OFF | E15: 45903 | F15: 46134 | G15: CLOSED
A16: LINEN CLUB | B16: ATV | C16: AW'25 | D16: BUY 4 GET 2000/- OFF | E16: 45903 | F16: 46134 | G16: CLOSED
A17: U. S. POLO | B17: ATV | C17: AW'25 | D17: BUY 16999/- GET 3000/- 0FF | E17: 45941 | F17: 46001 | G17: CLOSED | H17: US POLO AW'25 ATV OFFER ARTWORK.pdf
A18: U. S. POLO | B18: ATV | C18: AW'25 | D18: BUY 12999/- GET 2000/- 0FF | E18: 45941 | F18: 46001 | G18: CLOSED
A19: U. S. POLO | B19: ATV | C19: AW'25 | D19: BUY 7999/- GET 1000/- 0FF | E19: 45941 | F19: 46001 | G19: CLOSED
A20: U. S. POLO KIDS | B20: ATV | C20: AW'25 | D20: BUY 10999/- GET 2000/- 0FF | E20: 45941 | F20: 45961 | G20: CLOSED | H20: US POLO KIDS AW'25 ATV OFFER ARTWORK.pdf
A21: U. S. POLO KIDS | B21: ATV | C21: AW'25 | D21: BUY 6999/- GET 1000/- 0FF | E21: 45941 | F21: 45961 | G21: CLOSED
A22: U. S. POLO KIDS | B22: ATV | C22: AW'25 | D22: BUY 3999/- GET 500/- 0FF | E22: 45941 | F22: 45961 | G22: CLOSED
A23: ARROW | B23: ATV | C23: AW'25 | D23: BUY 14999/- GET 3000/- 0FF | E23: 45962 | F23: 46001 | G23: CLOSED | H23: ARROW 2ND ATV OFFER AW'25 ARTWORK.pdf
A24: ARROW | B24: ATV | C24: AW'25 | D24: BUY 10999/- GET 2000/- 0FF | E24: 45962 | F24: 46001 | G24: CLOSED
A25: ARROW | B25: ATV | C25: AW'25 | D25: BUY 6999/- GET 1000/- 0FF | E25: 45962 | F25: 46001 | G25: CLOSED
A26: FLYING MACHINE | B26: ATV | C26: AW'25 | D26: BUY 10999/- GET 2000/- 0FF | E26: 45962 | F26: 46001 | G26: CLOSED | H26: FM ATV OFFER 2ND AW'25 ARTWORK.pdf
A27: FLYING MACHINE | B27: ATV | C27: AW'25 | D27: BUY 5999/- GET 1000/- 0FF | E27: 45962 | F27: 46001 | G27: CLOSED
A28: FLYING MACHINE | B28: ATV | C28: AW'25 | D28: BUY 3999/- GET 500/- 0FF | E28: 45962 | F28: 46001 | G28: CLOSED
A29: U. S. POLO KIDS | B29: ATV | C29: AW'25 | D29: BUY 10999/- GET 2000/- 0FF | E29: 45962 | F29: 46001 | G29: CLOSED | H29: US POLO KIDS 2ND AW'25 ATV OFFER ARTWORK.pdf
A30: U. S. POLO KIDS | B30: ATV | C30: AW'25 | D30: BUY 5999/- GET 1000/- 0FF | E30: 45962 | F30: 46001 | G30: CLOSED
A31: U. S. POLO KIDS | B31: ATV | C31: AW'25 | D31: BUY 3999/- GET 500/- 0FF | E31: 45962 | F31: 46001 | G31: CLOSED
A32: SPYKAR | B32: ATV | C32: AW'25 | D32: BUY 14999/- GET 20% 0FF , BUY 7999/- GET 15% 0FF | E32: 45924 | F32: 45988 | G32: CLOSED | H32: SPYKAR AW'25 ATV OFFER ARTWORK.pdf
A33: SPYKAR | B33: ATV | C33: AW'25 | D33: MEN'S B2G2 OR BUY 2 GET 30% OFF, BUY 1 GET 20% OFF | E33: 45989 | F33: 45991 | G33: CLOSED | H33: SPYKAR AW'25 BLACK FRIDAY MEN'S ARTWORK.pdf
A34: SPYKAR | B34: ATV | C34: AW'25 | D34: WOMEN'S B2G2 OR BUY 2 GET 30% OFF, BUY 1 GET 20% OFF | E34: 45989 | F34: 45991 | G34: CLOSED | H34: SPYKAR AW'25 BLACK FRIDAY WOMEN'S ARTWORK.pdf
A35: SPYKAR | B35: ATV | C35: AW'25 | D35: MEN'S BUY 4 GET 40% OFF, BUY 2 GET 30% OFF, BUY 1 GET 20% OFF | E35: 45992 | F35: 46001 | G35: CLOSED | H35: SPYKAR MEN'S AW'25 2ND ATV OFFER ARTWORK.pdf
A36: SPYKAR | B36: ATV | C36: AW'25 | D36: WOMEN'S BUY 4 GET 40% OFF, BUY 2 GET 30% OFF, BUY 1 GET 20% OFF | E36: 45992 | F36: 46001 | G36: CLOSED | H36: SPYKAR WOMENS AW'25 2ND ATV OFFER ARTWORK.pdf
A37: LINEN CLUB | B37: EOSS | C37: AW'25 | D37: B1-20%, B2-30%, OR B3 & ABOVE 40% | E37: 45999 | F37: 46009 | G37: CLOSED | H37: LINEN CLUB AW'25 EOSS OFFER ARTWORK..pdf
A38: FLYING MACHINE | B38: EOSS | C38: AW'25 | D38: BUY 1-20% & BUY-2-30% | E38: 46002 | F38: 46009 | G38: CLOSED | H38: FM EOSS OFFER AW'25 ARTWORK.pdf
A39: SPYKAR | B39: EOSS | C39: AW'25 | D39: MEN'S BUY 1 GET 30% OFF, BUY 2 GET 40% OFF & BUY 4 GET 50% OFF | E39: 46002 | F39: 46015 | G39: CLOSED | H39: SPYKAR MEN EOSS OFFER B4G50, B2G40, B1G30 ARTWORK.pdf
A40: SPYKAR | B40: EOSS | C40: AW'25 | D40: WOMEN'S BUY 1 GET 40% OFF, BUY 2 GET 50% OFF | E40: 46002 | F40: 46015 | G40: CLOSED | H40: SPYKAR WOMEN EOSS OFFER B2G50, B1G40 ARTWORK.pdf
...

Sheet SUPPLIER DATA BASE
A1: PARTY NAME | B1: Location | C1: Brand Name | D1: Credit Days | E1: CD | F1: Agency Company | G1: Agent Name | H1: Agent Number | I1: Agency Accounts Name | J1: Accounts Desk Number | K1: Account Holder Name | L1: Bank Account | M1: IFSC Code
A2: A P TEXTILES | B2: - | C2: - | D2: - | E2: - | F2: - | G2: - | H2: - | I2: - | J2: - | K2: - | L2: - | M2: -
A3: AARI | B3: - | C3: - | D3: - | E3: - | F3: - | G3: - | H3: - | I3: - | J3: - | K3: - | L3: - | M3: -
A4: AARNA VENTURES PRIVATE LIMITED | B4: - | C4: - | D4: - | E4: - | F4: - | G4: - | H4: - | I4: - | J4: - | K4: - | L4: - | M4: -
A5: AAROHI FASHION | B5: - | C5: - | D5: - | E5: - | F5: - | G5: - | H5: - | I5: - | J5: - | K5: - | L5: - | M5: -
A6: AD EDGE (VH-KANK) | B6: - | C6: - | D6: - | E6: - | F6: - | G6: - | H6: - | I6: - | J6: - | K6: - | L6: - | M6: -
A7: ADITYA BIRLA | B7: - | C7: - | D7: - | E7: - | F7: - | G7: - | H7: - | I7: - | J7: - | K7: - | L7: - | M7: -
A8: ADITYA VISION LTD (JH) | B8: - | C8: - | D8: - | E8: - | F8: - | G8: - | H8: - | I8: - | J8: - | K8: - | L8: - | M8: -
A9: AGWANI FASHION | B9: - | C9: SUCCESS | D9: - | E9: - | F9: - | G9: - | H9: - | I9: - | J9: - | K9: - | L9: - | M9: -
A10: AJJAWAM DESIGNER PRIVATE LIMITED | B10: SURAT | C10: - | D10: NO | E10: - | F10: SURYAM TEXTILE AGENCY | G10: AKASH | H10: 91044 89871 | I10: - | J10: - | K10: AJJAWAM DESIGNER PRIVATE LIMITED | L10: 925020021188499 | M10: UTIB0004665
A11: ANAND FABRICS | B11: - | C11: - | D11: - | E11: - | F11: - | G11: - | H11: - | I11: - | J11: - | K11: - | L11: - | M11: -
A12: ARVIND LIMITED | B12: - | C12: - | D12: - | E12: - | F12: - | G12: - | H12: - | I12: - | J12: - | K12: - | L12: - | M12: -
... A14: ARVIND LIMITED (KAR) | B14: - | C14: - | D14: - | E14: - | F14: - | G14: - | H14: - | I14: - | J14: - | K14: - | L14: - | M14: -
A15: AS TEXTILE | B15: SURAT | C15: - | D15: 30 | E15: 0.09 | F15: SURYAM TEXTILE AGENCY | G15: AKASH | H15: 91044 89871 | I15: - | J15: - | K15: AS TEXTILE | L15: 50200012846193 | M15: HDFC0001249
A16: ASHMITA BOUTIQUE PVT. LTD. | B16: KOLKATA | C16: - | D16: 60 | E16: 0.03 | F16: NEPOLIAN | G16: MUKESH | H16: 9831451670 | I16: - | J16: - | K16: ASHMITA BOUTIQUE PVT. LTD. | L16: 627951000036 | M16: ICICI0006279
A17: B B FASHIONS | B17: - | C17: - | D17: - | E17: - | F17: - | G17: - | H17: - | I17: - | J17: - | K17: B B FASHIONS | L17: 4913058844 | M17: KKBK0004599
A18: B.K ENTERPRISES | B18: RANCHI | C18: LITTLE PINK | D18: - | E18: - | F18: - | G18: - | H18: - | I18: - | J18: - | K18: - | L18: - | M18: -
A19: B.K.SILK MILLS NX LLP | B19: SURAT | C19: - | D19: NO | E19: - | F19: SURYAM TEXTILE AGENCY | G19: AKASH | H19: 91044 89871 | I19: - | J19: - | K19: B.K.SILK MILLS NX LLP | L19: 58451000050 | M19: ICIC0000584
A20: BALTIC LEI INDIA PRIVATE LIMITED | B20: - | C20: - | D20: - | E20: - | F20: - | G20: - | H20: - | I20: - | J20: - | K20: - | L20: - | M20: -
A21: BANSAL TEXTILES | B21: - | C21: - | D21: - | E21: - | F21: - | G21: - | H21: - | I21: - | J21: - | K21: - | L21: - | M21: -
A22: BINOD KUMAR SINGHANIA | B22: - | C22: - | D22: - | E22: - | F22: - | G22: - | H22: - | I22: - | J22: - | K22: - | L22: - | M22: -
A23: BLAZO CLOTHING MANUFACTURING CO PVT LTD | B23: - | C23: BLAZO | D23: - | E23: - | F23: - | G23: - | H23: - | I23: - | J23: - | K23: - | L23: - | M23: -
A24: C2D VENTURES LLP | B24: DHANBAD | C24: WELSPUN, VAN HEUSEN | D24: 15 | E24: 5 | F24: DIRECT | G24: - | H24: - | I24: - | J24: - | K24: C2D VENTURES LLP | L24: 50484840037 | M24: IDIB000D600
A25: COMNET SOLUTIONS | B25: - | C25: - | D25: - | E25: - | F25: - | G25: - | H25: - | I25: - | J25: - | K25: - | L25: - | M25: -
A26: CRYSTAL BY TARUN DESIGN | B26: DELHI | C26: - | D26: - | E26: - | F26: - | G26: - | H26: - | I26: - | J26: - | K26: - | L26: - | M26: -
A27: D APPAREL | B27: RANCHI | C27: KHUSHAL/STATUS QUO | D27: - | E27: - | F27: - | G27: - | H27: - | I27: - | J27: - | K27: D APPAREL | L27: 722501010050397 | M27: UBIN0572250
A28: D D APPARELS | B28: RANCHI | C28: SWEET DREAMS | D28: NO | E28: - | F28: - | G28: - | H28: - | I28: - | J28: - | K28: D D APPARELS | L28: 029205007835 | M28: ICIC0000292
A29: D D DEVELOPER | B29: BHAGALPUR | C29: JOCKEY | D29: - | E29: - | F29: - | G29: - | H29: - | I29: - | J29: - | K29: - | L29: - | M29: -
A30: D D SALES CO | B30: RANCHI | C30: KILLER | D30: NO | E30: - | F30: - | G30: - | H30: - | I30: - | J30: - | K30: D D SALES CO | L30: 29205007835 | M30: ICIC0000292
A31: D S CREATION | B31: KOLKATA | C31: YES MAAM | D31: 60 | E31: 0.03 | F31: NEPOLIAN | G31: MUKESH | H31: 9831451670 | I31: - | J31: - | K31: D S CREATION | L31: 9830047013 | M31: KKBK0006562
A32: D.D.SALES CO | B32: RANCHI | C32: JOCKEY, KILLER, NEXTBIT | D32: - | E32: - | F32: - | G32: - | H32: - | I32: - | J32: - | K32: - | L32: - | M32: -
A33: D.S.CREATION | B33: - | D33: - | E33: - | F33: - | G33: - | H33: - | I33: - | J33: - | K33: - | L33: - | M33: -
A34: DAULAL NANDLAL | B34: - | C34: - | D34: - | E34: - | F34: - | G34: - | H34: - | I34: - | J34: - | K34: - | L34: - | M34: -
A35: DEVTA GARMENTS | B35: - | C35: - | D35: - | E35: - | F35: - | G35: - | H35: - | I35: - | J35: - | K35: - | L35: - | M35: -
A36: DHANVI RITIKA FASHION | B36: RANCHI | C36: SANSKAR | D36: - | E36: - | F36: - | G36: - | H36: - | I36: - | J36: - | K36: - | L36: - | M36: -
A37: DIL SE | B37: - | C37: - | D37: - | E37: - | F37: - | G37: - | H37: - | I37: - | J37: - | K37: DIL SE | L37: 11197610000574 | M37: HDFC0001119
A38: DIYA CREATION | B38: MUMBAI | C38: - | D38: 30 | E38: 0.05 | F38: - | G38: MAULIK AJMERA | H38: 9930050607 | I38: - | J38: - | K38: DIYA CREATION | L38: 199502000000874 | M38: IOBA0001995
A39: ELA DESIGNER PRIVATE LIMITED | B39: - | C39: - | D39: - | E39: - | F39: - | G39: - | H39: - | I39: - | J39: - | K39: - | L39: - | M39: -
A40: ELITE EDITION | B40: SURAT | C40: - | D40: 70 | E40: 0.1 | F40: SURYAM TEXTILE AGENCY | G40: AKASH | H40: 91044 89871 | I40: - | J40: - | K40: ELITE EDITION | L40: 183605501803 | M40: ICIC0001836
A41: EMPORIO SIDDHARTH SALES PRIVATE LIMITED | B41: PATNA | C41: GOCOLOURS | D41: 30 | E41: 0.02 | F41: - | G41: - | H41: - | I41: - | J41: - | K41: EMPORIO SIDDHARTH SALES PRIVATE LIMITED | L41: 50200111968638 | M41: HDFC000186
...

Sheet INVOICE DETAILS.
A1: Other Invoice Details | F1: =SUBTOTAL(3,F3:F1994) -> 1259 | G1: TOTAL INVOICE COUNT | H1: =IF(SUBTOTAL(9,H3:H1994)=0," ",SUBTOTAL(9,H3:H1994)) -> 54487 | I1: =IF(SUBTOTAL(9,I3:I1994)=0," ",SUBTOTAL(9,I3:I1994)) -> 67763896 | J1: =IF(SUBTOTAL(3,J3:J1994)-F1>0,"NEED TO UPDATE: " & (SUBTOTAL(3,J3:J1994)-F1),"LAST UPDATE: " & TEXT(MAX(G3:G1994),"dd-mmmm-yyyy")) -> NEED TO UPDATE: 219 | Q1: =IF(SUBTOTAL(9,Q3:Q994)=0," ",SUBTOTAL(9,Q3:Q994)) -> 2350486 | S1: =IF(SUBTOTAL(9,S3:S994)=0," ",SUBTOTAL(9,S3:S994)) -> 96300.6 | T1: =IF(SUBTOTAL(9,T3:T994)=0," ",SUBTOTAL(9,T3:T994)) -> 2145
A2: Supplier Name | B2: Brand Name | C2: Agency Company | D2: Credit Days | E2: CD % | F2: Invoice No | G2: Invoice Date | H2: Invoice Qty | I2: Invoice Value | J2: Invoice Soft Copy | K2: PT File Excel Sheet | L2: TEN Uploaded Date | M2: Invoice Ageing | N2: Bank Name | O2: Bank Account | P2: IFSC Code | Q2: Payment Amount | R2: Payment Date | S2: CD Amount | T2: GR Amount | U2: Remarks | V2: Accounting Year
A3: D D SALES CO | B3: =IF($A$3=" "," ", IFERROR( VLOOKUP($A3,'SUPPLIER DATA BASE'!$A$2:$M$936,3,0),"")) -> KILLER | C3: =IF($A$3=" "," ", IFERROR( VLOOKUP($A3,'SUPPLIER DATA BASE'!$A$2:$F$936,6,0),"")) -> - | D3: =IF($A$3=" "," ", IFERROR( VLOOKUP($A3,'SUPPLIER DATA BASE'!$A$2:$G$936,4,0),"")) -> NO | E3: =IF($A$3=" "," ", IFERROR( VLOOKUP($A3,'SUPPLIER DATA BASE'!$A$2:$H$936,5,0),"")) -> - | F3: JKL-159 | G3: 45593 | H3: 22 | I3: 36223 | J3: DD SALES -159.pdf | K3: - | L3: - | M3: =IF(G3="", "", (TODAY() - G3) & " Days") -> 595 Days | N3: =IF($A$3=" "," ", IFERROR( VLOOKUP($A3,'SUPPLIER DATA BASE'!$A$2:$O$936,11,0),"")) -> D D SALES CO | O3: =IF($A$3=" "," ", IFERROR( VLOOKUP($A3,'SUPPLIER DATA BASE'!$A$2:$O$936,12,0),"")) -> 29205007835 | P3: =IF($A$3=" "," ", IFERROR( VLOOKUP($A3,'SUPPLIER DATA BASE'!$A$2:$O$936,13,0),"")) -> ICIC0000292 | V3: =IF(G3="","", IF(AND(G3>=DATE(2024,4,1),G3<=DATE(2025,3,31)),"FY 24-25", IF(AND(G3>=DATE(2025,4,1),G3<=DATE(2026,3,31)),"FY 25-26",IF(AND(G3>=DATE(2026,4,1),G3<=DATE(2027,3,31)),"FY 26-27","")))) -> FY 24-25
A4: ADITYA BIRLA | B4: =IF($A$3=" "," ", IFERROR( VLOOKUP($A4,'SUPPLIER DATA BASE'!$A$2:$M$936,3,0),"")) -> - | C4: =IF($A$3=" "," ", IFERROR( VLOOKUP($A4,'SUPPLIER DATA BASE'!$A$2:$F$936,6,0),"")) -> - | D4: =IF($A$3=" "," ", IFERROR( VLOOKUP($A4,'SUPPLIER DATA BASE'!$A$2:$G$936,4,0),"")) -> - | E4: =IF($A$3=" "," ", IFERROR( VLOOKUP($A4,'SUPPLIER DATA BASE'!$A$2:$H$936,5,0),"")) -> - | F4: MSF2252000010422 | G4: 45876 | H4: 3 | I4: 6074.1 | J4: ADITYA BIRLA -MSF2252000010422.pdf | K4: - | L4: - | M4: =IF(G4="", "", (TODAY() - G4) & " Days") -> 312 Days | N4: =IF($A$3=" "," ", IFERROR( VLOOKUP($A4,'SUPPLIER DATA BASE'!$A$2:$O$936,11,0),"")) -> - | O4: =IF($A$3=" "," ", IFERROR( VLOOKUP($A4,'SUPPLIER DATA BASE'!$A$2:$O$936,12,0),"")) -> - | P4: =IF($A$3=" "," ", IFERROR( VLOOKUP($A4,'SUPPLIER DATA BASE'!$A$2:$O$936,13,0),"")) -> - | V4: =IF(G4="","", IF(AND(G4>=DATE(2024,4,1),G4<=DATE(2025,3,31)),"FY 24-25", IF(AND(G4>=DATE(2025,4,1),G4<=DATE(2026,3,31)),"FY 25-26",IF(AND(G4>=DATE(2026,4,1),G4<=DATE(2027,3,31)),"FY 26-27","")))) -> FY 25-26
A5: ADITYA BIRLA | B5: =IF($A$3=" "," ", IFERROR( VLOOKUP($A5,'SUPPLIER DATA BASE'!$A$2:$M$936,3,0),"")) -> - | C5: =IF($A$3=" "," ", IFERROR( VLOOKUP($A5,'SUPPLIER DATA BASE'!$A$2:$F$936,6,0),"")) -> - | D5: =IF($A$3=" "," ", IFERROR( VLOOKUP($A5,'SUPPLIER DATA BASE'!$A$2:$G$936,4,0),"")) -> - | E5: =IF($A$3=" "," ", IFERROR( VLOOKUP($A5,'SUPPLIER DATA BASE'!$A$2:$H$936,5,0),"")) -> - | F5: MSF2251000012742 | G5: 45913 | H5: 7 | I5: 13088.75 | J5: ADITYA BIRLA -MSF2251000012742.PDF | K5: - | L5: - | M5: =IF(G5="", "", (TODAY() - G5) & " Days") -> 275 Days | N5: =IF($A$3=" "," ", IFERROR( VLOOKUP($A5,'SUPPLIER DATA BASE'!$A$2:$O$936,11,0),"")) -> - | O5: =IF($A$3=" "," ", IFERROR( VLOOKUP($A5,'SUPPLIER DATA BASE'!$A$2:$O$936,12,0),"")) -> - | P5: =IF($A$3=" "," ", IFERROR( VLOOKUP($A5,'SUPPLIER DATA BASE'!$A$2:$O$936,13,0),"")) -> - | V5: =IF(G5="","", IF(AND(G5>=DATE(2024,4,1),G5<=DATE(2025,3,31)),"FY 24-25", IF(AND(G5>=DATE(2025,4,1),G5<=DATE(2026,3,31)),"FY 25-26",IF(AND(G5>=DATE(2026,4,1),G5<=DATE(2027,3,31)),"FY 26-27","")))) -> FY 25-26
A6: ROOP LAXMI SAREES (P) LTD | B6: =IF($A$3=" "," ", IFERROR( VLOOKUP($A6,'SUPPLIER DATA BASE'!$A$2:$M$936,3,0),"")) -> रूप लक्ष्मी | C6: =IF($A$3=" "," ", IFERROR( VLOOKUP($A6,'SUPPLIER DATA BASE'!$A$2:$F$936,6,0),"")) -> - | D6: =IF($A$3=" "," ", IFERROR( VLOOKUP($A6,'SUPPLIER DATA BASE'!$A$2:$G$936,4,0),"")) -> - | E6: =IF($A$3=" "," ", IFERROR( VLOOKUP($A6,'SUPPLIER DATA BASE'!$A$2:$H$936,5,0),"")) -> - | F6: RL/8362/25-26 | G6: 45948 | H6: 18 | I6: 23877 | J6: Room Laxmi sarees 8362 (1).pdf | K6: - | L6: - | M6: =IF(G6="", "", (TODAY() - G6) & " Days") -> 240 Days | N6: =IF($A$3=" "," ", IFERROR( VLOOKUP($A6,'SUPPLIER DATA BASE'!$A$2:$O$936,11,0),"")) -> ROOP LAXMI SAREES (P) LTD | O6: =IF($A$3=" "," ", IFERROR( VLOOKUP($A6,'SUPPLIER DATA BASE'!$A$2:$O$936,12,0),"")) -> 0221083000003432 | P6: =IF($A$3=" "," ", IFERROR( VLOOKUP($A6,'SUPPLIER DATA BASE'!$A$2:$O$936,13,0),"")) -> SIBL0000221 | V6: =IF(G6="","", IF(AND(G6>=DATE(2024,4,1),G6<=DATE(2025,3,31)),"FY 24-25", IF(AND(G6>=DATE(2025,4,1),G6<=DATE(2026,3,31)),"FY 25-26",IF(AND(G6>=DATE(2026,4,1),G6<=DATE(2027,3,31)),"FY 26-27","")))) -> FY 25-26
A7: ROOP LAXMI SAREES (P) LTD | B7: =IF($A$3=" "," ", IFERROR( VLOOKUP($A7,'SUPPLIER DATA BASE'!$A$2:$M$936,3,0),"")) -> रूप लक्ष्मी | C7: =IF($A$3=" "," ", IFERROR( VLOOKUP($A7,'SUPPLIER DATA BASE'!$A$2:$F$936,6,0),"")) -> - | D7: =IF($A$3=" "," ", IFERROR( VLOOKUP($A7,'SUPPLIER DATA BASE'!$A$2:$G$936,4,0),"")) -> - | E7: =IF($A$3=" "," ", IFERROR( VLOOKUP($A7,'SUPPLIER DATA BASE'!$A$2:$H$936,5,0),"")) -> - | F7: RL/8360/25-26 | G7: 45948 | H7: 16 | I7: 67137 | J7: Roop laxmi sarees 8360 (1).pdf | K7: - | L7: - | M7: =IF(G7="", "", (TODAY() - G7) & " Days") -> 240 Days | N7: =IF($A$3=" "," ", IFERROR( VLOOKUP($A7,'SUPPLIER DATA BASE'!$A$2:$O$936,11,0),"")) -> ROOP LAXMI SAREES (P) LTD | O7: =IF($A$3=" "," ", IFERROR( VLOOKUP($A7,'SUPPLIER DATA BASE'!$A$2:$O$936,12,0),"")) -> 0221083000003432 | P7: =IF($A$3=" "," ", IFERROR( VLOOKUP($A7,'SUPPLIER DATA BASE'!$A$2:$O$936,13,0),"")) -> SIBL0000221 | V7: =IF(G7="","", IF(AND(G7>=DATE(2024,4,1),G7<=DATE(2025,3,31)),"FY 24-25", IF(AND(G7>=DATE(2025,4,1),G7<=DATE(2026,3,31)),"FY 25-26",IF(AND(G7>=DATE(2026,4,1),G7<=DATE(2027,3,31)),"FY 26-27","")))) -> FY 25-26
A8: D APPAREL | B8: =IF($A$3=" "," ", IFERROR( VLOOKUP($A8,'SUPPLIER DATA BASE'!$A$2:$M$936,3,0),"")) -> KHUSHAL/STATUS QUO | C8: =IF($A$3=" "," ", IFERROR( VLOOKUP($A8,'SUPPLIER DATA BASE'!$A$2:$F$936,6,0),"")) -> - | D8: =IF($A$3=" "," ", IFERROR( VLOOKUP($A8,'SUPPLIER DATA BASE'!$A$2:$G$936,4,0),"")) -> - | E8: =IF($A$3=" "," ", IFERROR( VLOOKUP($A8,'SUPPLIER DATA BASE'!$A$2:$H$936,5,0),"")) -> - | F8: DA/25-26/0605 | G8: 45952 | H8: 6 | I8: 25693 | J8: D APPAREL(KHUSHAAL)_INV0605_JSL.pdf | K8: - | L8: - | M8: =IF(G8="", "", (TODAY() - G8) & " Days") -> 236 Days | N8: =IF($A$3=" "," ", IFERROR( VLOOKUP($A8,'SUPPLIER DATA BASE'!$A$2:$O$936,11,0),"")) -> D APPAREL | O8: =IF($A$3=" "," ", IFERROR( VLOOKUP($A8,'SUPPLIER DATA BASE'!$A$2:$O$936,12,0),"")) -> 722501010050397 | P8: =IF($A$3=" "," ", IFERROR( VLOOKUP($A8,'SUPPLIER DATA BASE'!$A$2:$O$936,13,0),"")) -> UBIN0572250 | V8: =IF(G8="","", IF(AND(G8>=DATE(2024,4,1),G8<=DATE(2025,3,31)),"FY 24-25", IF(AND(G8>=DATE(2025,4,1),G8<=DATE(2026,3,31)),"FY 25-26",IF(AND(G8>=DATE(2026,4,1),G8<=DATE(2027,3,31)),"FY 26-27","")))) -> FY 25-26
A9: VISHAL MARKETING & CO. | B9: =IF($A$3=" "," ", IFERROR( VLOOKUP($A9,'SUPPLIER DATA BASE'!$A$2:$M$936,3,0),"")) -> - | C9: =IF($A$3=" "," ", IFERROR( VLOOKUP($A9,'SUPPLIER DATA BASE'!$A$2:$F$936,6,0),"")) -> - | D9: =IF($A$3=" "," ", IFERROR( VLOOKUP($A9,'SUPPLIER DATA BASE'!$A$2:$G$936,4,0),"")) -> - | E9: =IF($A$3=" "," ", IFERROR( VLOOKUP($A9,'SUPPLIER DATA BASE'!$A$2:$H$936,5,0),"")) -> - | F9: D/1212 | G9: 45986 | H9: 18 | I9: 59696 | J9: VISHAL MARKETING & CO(SPYKAR)_1212_2025-26.pdf | K9: - | L9: - | M9: =IF(G9="", "", (TODAY() - G9) & " Days") -> 202 Days | N9: =IF($A$3=" "," ", IFERROR( VLOOKUP($A9,'SUPPLIER DATA BASE'!$A$2:$O$936,11,0),"")) -> VISHAL MARKETING & CO. | O9: =IF($A$3=" "," ", IFERROR( VLOOKUP($A9,'SUPPLIER DATA BASE'!$A$2:$O$936,12,0),"")) -> 1091008700001025 | P9: =IF($A$3=" "," ", IFERROR( VLOOKUP($A9,'SUPPLIER DATA BASE'!$A$2:$O$936,13,0),"")) -> PUNB0109100 | V9: =IF(G9="","", IF(AND(G9>=DATE(2024,4,1),G9<=DATE(2025,3,31)),"FY 24-25", IF(AND(G9>=DATE(2025,4,1),G9<=DATE(2026,3,31)),"FY 25-26",IF(AND(G9>=DATE(2026,4,1),G9<=DATE(2027,3,31)),"FY 26-27","")))) -> FY 25-26
A10: ADITYA BIRLA | B10: =IF($A$3=" "," ", IFERROR( VLOOKUP($A10,'SUPPLIER DATA BASE'!$A$2:$M$936,3,0),"")) -> - | C10: =IF($A$3=" "," ", IFERROR( VLOOKUP($A10,'SUPPLIER DATA BASE'!$A$2:$F$936,6,0),"")) -> - | D10: =IF($A$3=" "," ", IFERROR( VLOOKUP($A10,'SUPPLIER DATA BASE'!$A$2:$G$936,4,0),"")) -> - | E10: =IF($A$3=" "," ", IFERROR( VLOOKUP($A10,'SUPPLIER DATA BASE'!$A$2:$H$936,5,0),"")) -> - | F10: MSF2251000022820 | G10: 46001 | H10: 7 | I10: 38685.2 | J10: ADITYA BIRLA -MSF2251000022820.pdf | K10: - | L10: - | M10: =IF(G10="", "", (TODAY() - G10) & " Days") -> 187 Days | N10: =IF($A$3=" "," ", IFERROR( VLOOKUP($A10,'SUPPLIER DATA BASE'!$A$2:$O$936,11,0),"")) -> - | O10: =IF($A$3=" "," ", IFERROR( VLOOKUP($A10,'SUPPLIER DATA BASE'!$A$2:$O$936,12,0),"")) -> - | P10: =IF($A$3=" "," ", IFERROR( VLOOKUP($A10,'SUPPLIER DATA BASE'!$A$2:$O$936,13,0),"")) -> - | V10: =IF(G10="","", IF(AND(G10>=DATE(2024,4,1),G10<=DATE(2025,3,31)),"FY 24-25", IF(AND(G10>=DATE(2025,4,1),G10<=DATE(2026,3,31)),"FY 25-26",IF(AND(G10>=DATE(2026,4,1),G10<=DATE(2027,3,31)),"FY 26-27","")))) -> FY 25-26
A11: ADITYA BIRLA | B11: =IF($A$3=" "," ", IFERROR( VLOOKUP($A11,'SUPPLIER DATA BASE'!$A$2:$M$936,3,0),"")) -> - | C11: =IF($A$3=" "," ", IFERROR( VLOOKUP($A11,'SUPPLIER DATA BASE'!$A$2:$F$936,6,0),"")) -> - | D11: =IF($A$3=" "," ", IFERROR( VLOOKUP($A11,'SUPPLIER DATA BASE'!$A$2:$G$936,4,0),"")) -> - | E11: =IF($A$3=" "," ", IFERROR( VLOOKUP($A11,'SUPPLIER DATA BASE'!$A$2:$H$936,5,0),"")) -> - | F11: MSF2251000022940 | G11: 46002 | H11: 23 | I11: 97197.17 | J11: ADITYA BIRLA -MSF2251000022940.pdf | K11: - | L11: - | M11: =IF(G11="", "", (TODAY() - G11) & " Days") -> 186 Days | N11: =IF($A$3=" "," ", IFERROR( VLOOKUP($A11,'SUPPLIER DATA BASE'!$A$2:$O$936,11,0),"")) -> - | O11: =IF($A$3=" "," ", IFERROR( VLOOKUP($A11,'SUPPLIER DATA BASE'!$A$2:$O$936,12,0),"")) -> - | P11: =IF($A$3=" "," ", IFERROR( VLOOKUP($A11,'SUPPLIER DATA BASE'!$A$2:$O$936,13,0),"")) -> - | V11: =IF(G11="","", IF(AND(G11>=DATE(2024,4,1),G11<=DATE(2025,3,31)),"FY 24-25", IF(AND(G11>=DATE(2025,4,1),G11<=DATE(2026,3,31)),"FY 25-26",IF(AND(G11>=DATE(2026,4,1),G11<=DATE(2027,3,31)),"FY 26-27","")))) -> FY 25-26
A12: ADITYA BIRLA | B12: =IF($A$3=" "," ", IFERROR( VLOOKUP($A12,'SUPPLIER DATA BASE'!$A$2:$M$936,3,0),"")) -> - | C12: =IF($A$3=" "," ", IFERROR( VLOOKUP($A12,'SUPPLIER DATA BASE'!$A$2:$F$936,6,0),"")) -> - | D12: =IF($A$3=" "," ", IFERROR( VLOOKUP($A12,'SUPPLIER DATA BASE'!$A$2:$G$936,4,0),"")) -> - | E12: =IF($A$3=" "," ", IFERROR( VLOOKUP($A12,'SUPPLIER DATA BASE'!$A$2:$H$936,5,0),"")) -> - | F12: MSF2251000923014 | G12: 46002 | H12: 22 | I12: 42886.53 | J12: ADITYA BIRLA -MSF2251000923014.pdf | K12: - | L12: - | M12: =IF(G12="", "", (TODAY() - G12) & " Days") -> 186 Days | N12: =IF($A$3=" "," ", IFERROR( VLOOKUP($A12,'SUPPLIER DATA BASE'!$A$2:$O$936,11,0),"")) -> - | O12: =IF($A$3=" "," ", IFERROR( VLOOKUP($A12,'SUPPLIER DATA BASE'!$A$2:$O$936,12,0),"")) -> - | P12: =IF($A$3=" "," ", IFERROR( VLOOKUP($A12,'SUPPLIER DATA BASE'!$A$2:$O$936,13,0),"")) -> - | V12: =IF(G12="","", IF(AND(G12>=DATE(2024,4,1),G12<=DATE(2025,3,31)),"FY 24-25", IF(AND(G12>=DATE(2025,4,1),G12<=DATE(2026,3,31)),"FY 25-26",IF(AND(G12>=DATE(2026,4,1),G12<=DATE(2027,3,31)),"FY 26-27","")))) -> FY 25-26
A13: ADITYA BIRLA | B13: =IF($A$3=" "," ", IFERROR( VLOOKUP($A13,'SUPPLIER DATA BASE'!$A$2:$M$936,3,0),"")) -> - | C13: =IF($A$3=" "," ", IFERROR( VLOOKUP($A13,'SUPPLIER DATA BASE'!$A$2:$F$936,6,0),"")) -> - | D13: =IF($A$3=" "," ", IFERROR( VLOOKUP($A13,'SUPPLIER DATA BASE'!$A$2:$G$936,4,0),"")) -> - | E13: =IF($A$3=" "," ", IFERROR( VLOOKUP($A13,'SUPPLIER DATA BASE'!$A$2:$H$936,5,0),"")) -> - | F13: MSF2252000024323 | G13: 46013 | H13: 85 | I13: 157878.07 | J13: ADITYA BIRLA -MSF2252000024323.pdf | K13: - | L13: - | M13: =IF(G13="", "", (TODAY() - G13) & " Days") -> 175 Days | N13: =IF($A$3=" "," ", IFERROR( VLOOKUP($A13,'SUPPLIER DATA BASE'!$A$2:$O$936,11,0),"")) -> - | O13: =IF($A$3=" "," ", IFERROR( VLOOKUP($A13,'SUPPLIER DATA BASE'!$A$2:$O$936,12,0),"")) -> - | P13: =IF($A$3=" "," ", IFERROR( VLOOKUP($A13,'SUPPLIER DATA BASE'!$A$2:$O$936,13,0),"")) -> - | V13: =IF(G13="","", IF(AND(G13>=DATE(2024,4,1),G13<=DATE(2025,3,31)),"FY 24-25", IF(AND(G13>=DATE(2025,4,1),G13<=DATE(2026,3,31)),"FY 25-26",IF(AND(G13>=DATE(2026,4,1),G13<=DATE(2027,3,31)),"FY 26-27","")))) -> FY 25-26
A14: SOUL INDIA | B14: =IF($A$3=" "," ", IFERROR( VLOOKUP($A14,'SUPPLIER DATA BASE'!$A$2:$M$936,3,0),"")) -> - | C14: =IF($A$3=" "," ", IFERROR( VLOOKUP($A14,'SUPPLIER DATA BASE'!$A$2:$F$936,6,0),"")) -> - | D14: =IF($A$3=" "," ", IFERROR( VLOOKUP($A14,'SUPPLIER DATA BASE'!$A$2:$G$936,4,0),"")) -> - | E14: =IF($A$3=" "," ", IFERROR( VLOOKUP($A14,'SUPPLIER DATA BASE'!$A$2:$H$936,5,0),"")) -> - | F14: EOS1-48 | G14: 46017 | H14: 103 | I14: 149799.69 | J14: SOUL INDIA EOS1-48.pdf | K14: - | L14: - | M14: =IF(G14="", "", (TODAY() - G14) & " Days") -> 171 Days | N14: =IF($A$3=" "," ", IFERROR( VLOOKUP($A14,'SUPPLIER DATA BASE'!$A$2:$O$936,11,0),"")) -> SOUL INDIA | O14: =IF($A$3=" "," ", IFERROR( VLOOKUP($A14,'SUPPLIER DATA BASE'!$A$2:$O$936,12,0),"")) -> 250705501258 | P14: =IF($A$3=" "," ", IFERROR( VLOOKUP($A14,'SUPPLIER DATA BASE'!$A$2:$O$936,13,0),"")) -> ICIC0002507 | V14: =IF(G14="","", IF(AND(G14>=DATE(2024,4,1),G14<=DATE(2025,3,31)),"FY 24-25", IF(AND(G14>=DATE(2025,4,1),G14<=DATE(2026,3,31)),"FY 25-26",IF(AND(G14>=DATE(2026,4,1),G14<=DATE(2027,3,31)),"FY 26-27","")))) -> FY 25-26
... A17: D S CREATION | B17: =IF($A$3=" "," ", IFERROR( VLOOKUP($A17,'SUPPLIER DATA BASE'!$A$2:$M$936,3,0),"")) -> YES MAAM | C17: =IF($A$3=" "," ", IFERROR( VLOOKUP($A17,'SUPPLIER DATA BASE'!$A$2:$F$936,6,0),"")) -> NEPOLIAN | D17: =IF($A$3=" "," ", IFERROR( VLOOKUP($A17,'SUPPLIER DATA BASE'!$A$2:$G$936,4,0),"")) -> 60 | E17: =IF($A$3=" "," ", IFERROR( VLOOKUP($A17,'SUPPLIER DATA BASE'!$A$2:$H$936,5,0),"")) -> 0.03 | F17: DS/5296/25-26 | G17: 46020 | H17: 1 | I17: 4065 | J17: D S creation 5296.pdf | K17: - | L17: - | M17: =IF(G17="", "", (TODAY() - G17) & " Days") -> 168 Days | N17: =IF($A$3=" "," ", IFERROR( VLOOKUP($A17,'SUPPLIER DATA BASE'!$A$2:$O$936,11,0),"")) -> D S CREATION | O17: =IF($A$3=" "," ", IFERROR( VLOOKUP($A17,'SUPPLIER DATA BASE'!$A$2:$O$936,12,0),"")) -> 9830047013 | P17: =IF($A$3=" "," ", IFERROR( VLOOKUP($A17,'SUPPLIER DATA BASE'!$A$2:$O$936,13,0),"")) -> KKBK0006562 | V17: =IF(G17="","", IF(AND(G17>=DATE(2024,4,1),G17<=DATE(2025,3,31)),"FY 24-25", IF(AND(G17>=DATE(2025,4,1),G17<=DATE(2026,3,31)),"FY 25-26",IF(AND(G17>=DATE(2026,4,1),G17<=DATE(2027,3,31)),"FY 26-27","")))) -> FY 25-26
A18: PLAZER FABRICS | B18: =IF($A$3=" "," ", IFERROR( VLOOKUP($A18,'SUPPLIER DATA BASE'!$A$2:$M$936,3,0),"")) -> - | C18: =IF($A$3=" "," ", IFERROR( VLOOKUP($A18,'SUPPLIER DATA BASE'!$A$2:$F$936,6,0),"")) -> - | D18: =IF($A$3=" "," ", IFERROR( VLOOKUP($A18,'SUPPLIER DATA BASE'!$A$2:$G$936,4,0),"")) -> - | E18: =IF($A$3=" "," ", IFERROR( VLOOKUP($A18,'SUPPLIER DATA BASE'!$A$2:$H$936,5,0),"")) -> - | F18: 2265 | G18: 46024 | H18: 11 | I18: 8377 | J18: PLAZER FABRICS -2265.pdf | K18: - | L18: - | M18: =IF(G18="", "", (TODAY() - G18) & " Days") -> 164 Days | N18: =IF($A$3=" "," ", IFERROR( VLOOKUP($A18,'SUPPLIER DATA BASE'!$A$2:$O$936,11,0),"")) -> PLAZER FABRICS | O18: =IF($A$3=" "," ", IFERROR( VLOOKUP($A18,'SUPPLIER DATA BASE'!$A$2:$O$936,12,0),"")) -> 50200014256984 | P18: =IF($A$3=" "," ", IFERROR( VLOOKUP($A18,'SUPPLIER DATA BASE'!$A$2:$O$936,13,0),"")) -> HDFC0002834 | V18: =IF(G18="","", IF(AND(G18>=DATE(2024,4,1),G18<=DATE(2025,3,31)),"FY 24-25", IF(AND(G18>=DATE(2025,4,1),G18<=DATE(2026,3,31)),"FY 25-26",IF(AND(G18>=DATE(2026,4,1),G18<=DATE(2027,3,31)),"FY 26-27","")))) -> FY 25-26
A19: P R MODI AND SONS | B19: =IF($A$3=" "," ", IFERROR( VLOOKUP($A19,'SUPPLIER DATA BASE'!$A$2:$M$936,3,0),"")) -> - | C19: =IF($A$3=" "," ", IFERROR( VLOOKUP($A19,'SUPPLIER DATA BASE'!$A$2:$F$936,6,0),"")) -> - | D19: =IF($A$3=" "," ", IFERROR( VLOOKUP($A19,'SUPPLIER DATA BASE'!$A$2:$G$936,4,0),"")) -> - | E19: =IF($A$3=" "," ", IFERROR( VLOOKUP($A19,'SUPPLIER DATA BASE'!$A$2:$H$936,5,0),"")) -> - | F19: 19221 | G19: 46024 | H19: 15 | I19: 21920 | J19: P R MODI AND SON'S -19221.pdf | K19: - | L19: - | M19: =IF(G19="", "", (TODAY() - G19) & " Days") -> 164 Days | N19: =IF($A$3=" "," ", IFERROR( VLOOKUP($A19,'SUPPLIER DATA BASE'!$A$2:$O$936,11,0),"")) -> P R MODI AND SONS | O19: =IF($A$3=" "," ", IFERROR( VLOOKUP($A19,'SUPPLIER DATA BASE'!$A$2:$O$936,12,0),"")) -> 490930150000030 | P19: =IF($A$3=" "," ", IFERROR( VLOOKUP($A19,'SUPPLIER DATA BASE'!$A$2:$O$936,13,0),"")) -> BKID0004909 | V19: =IF(G19="","", IF(AND(G19>=DATE(2024,4,1),G19<=DATE(2025,3,31)),"FY 24-25", IF(AND(G19>=DATE(2025,4,1),G19<=DATE(2026,3,31)),"FY 25-26",IF(AND(G19>=DATE(2026,4,1),G19<=DATE(2027,3,31)),"FY 26-27","")))) -> FY 25-26
A20: P R MODI AND SONS | B20: =IF($A$3=" "," ", IFERROR( VLOOKUP($A20,'SUPPLIER DATA BASE'!$A$2:$M$936,3,0),"")) -> - | C20: =IF($A$3=" "," ", IFERROR( VLOOKUP($A20,'SUPPLIER DATA BASE'!$A$2:$F$936,6,0),"")) -> - | D20: =IF($A$3=" "," ", IFERROR( VLOOKUP($A20,'SUPPLIER DATA BASE'!$A$2:$G$936,4,0),"")) -> - | E20: =IF($A$3=" "," ", IFERROR( VLOOKUP($A20,'SUPPLIER DATA BASE'!$A$2:$H$936,5,0),"")) -> - | F20: 19222 | G20: 46024 | H20: 12 | I20: 12231 | J20: P R MODI AND SON'S -19222.pdf | K20: - | L20: - | M20: =IF(G20="", "", (TODAY() - G20) & " Days") -> 164 Days | N20: =IF($A$3=" "," ", IFERROR( VLOOKUP($A20,'SUPPLIER DATA BASE'!$A$2:$O$936,11,0),"")) -> P R MODI AND SONS | O20: =IF($A$3=" "," ", IFERROR( VLOOKUP($A20,'SUPPLIER DATA BASE'!$A$2:$O$936,12,0),"")) -> 490930150000030 | P20: =IF($A$3=" "," ", IFERROR( VLOOKUP($A20,'SUPPLIER DATA BASE'!$A$2:$O$936,13,0),"")) -> BKID0004909 | V20: =IF(G20="","", IF(AND(G20>=DATE(2024,4,1),G20<=DATE(2025,3,31)),"FY 24-25", IF(AND(G20>=DATE(2025,4,1),G20<=DATE(2026,3,31)),"FY 25-26",IF(AND(G20>=DATE(2026,4,1),G20<=DATE(2027,3,31)),"FY 26-27","")))) -> FY 25-26
A21: P R MODI AND SONS | B21: =IF($A$3=" "," ", IFERROR( VLOOKUP($A21,'SUPPLIER DATA BASE'!$A$2:$M$936,3,0),"")) -> - | C21: =IF($A$3=" "," ", IFERROR( VLOOKUP($A21,'SUPPLIER DATA BASE'!$A$2:$F$936,6,0),"")) -> - | D21: =IF($A$3=" "," ", IFERROR( VLOOKUP($A21,'SUPPLIER DATA BASE'!$A$2:$G$936,4,0),"")) -> - | E21: =IF($A$3=" "," ", IFERROR( VLOOKUP($A21,'SUPPLIER DATA BASE'!$A$2:$H$936,5,0),"")) -> - | F21: 19220 | G21: 46024 | H21: 62 | I21: 59442 | J21: P R MODI AND SON'S -19220.pdf | K21: - | L21: - | M21: =IF(G21="", "", (TODAY() - G21) & " Days") -> 164 Days | N21: =IF($A$3=" "," ", IFERROR( VLOOKUP($A21,'SUPPLIER DATA BASE'!$A$2:$O$936,11,0),"")) -> P R MODI AND SONS | O21: =IF($A$3=" "," ", IFERROR( VLOOKUP($A21,'SUPPLIER DATA BASE'!$A$2:$O$936,12,0),"")) -> 490930150000030 | P21: =IF($A$3=" "," ", IFERROR( VLOOKUP($A21,'SUPPLIER DATA BASE'!$A$2:$O$936,13,0),"")) -> BKID0004909 | V21: =IF(G21="","", IF(AND(G21>=DATE(2024,4,1),G21<=DATE(2025,3,31)),"FY 24-25", IF(AND(G21>=DATE(2025,4,1),G21<=DATE(2026,3,31)),"FY 25-26",IF(AND(G21>=DATE(2026,4,1),G21<=DATE(2027,3,31)),"FY 26-27","")))) -> FY 25-26
A22: P R MODI AND SONS | B22: =IF($A$3=" "," ", IFERROR( VLOOKUP($A22,'SUPPLIER DATA BASE'!$A$2:$M$936,3,0),"")) -> - | C22: =IF($A$3=" "," ", IFERROR( VLOOKUP($A22,'SUPPLIER DATA BASE'!$A$2:$F$936,6,0),"")) -> - | D22: =IF($A$3=" "," ", IFERROR( VLOOKUP($A22,'SUPPLIER DATA BASE'!$A$2:$G$936,4,0),"")) -> - | E22: =IF($A$3=" "," ", IFERROR( VLOOKUP($A22,'SUPPLIER DATA BASE'!$A$2:$H$936,5,0),"")) -> - | F22: 19240 | G22: 46025 | H22: 2 | I22: 7236 | J22: P R MODI AND SON'S -19240.pdf | K22: - | L22: - | M22: =IF(G22="", "", (TODAY() - G22) & " Days") -> 163 Days | N22: =IF($A$3=" "," ", IFERROR( VLOOKUP($A22,'SUPPLIER DATA BASE'!$A$2:$O$936,11,0),"")) -> P R MODI AND SONS | O22: =IF($A$3=" "," ", IFERROR( VLOOKUP($A22,'SUPPLIER DATA BASE'!$A$2:$O$936,12,0),"")) -> 490930150000030 | P22: =IF($A$3=" "," ", IFERROR( VLOOKUP($A22,'SUPPLIER DATA BASE'!$A$2:$O$936,13,0),"")) -> BKID0004909 | V22: =IF(G22="","", IF(AND(G22>=DATE(2024,4,1),G22<=DATE(2025,3,31)),"FY 24-25", IF(AND(G22>=DATE(2025,4,1),G22<=DATE(2026,3,31)),"FY 25-26",IF(AND(G22>=DATE(2026,4,1),G22<=DATE(2027,3,31)),"FY 26-27","")))) -> FY 25-26
A23: C2D VENTURES LLP | B23: =IF($A$3=" "," ", IFERROR( VLOOKUP($A23,'SUPPLIER DATA BASE'!$A$2:$M$936,3,0),"")) -> WELSPUN, VAN HEUSEN | C23: =IF($A$3=" "," ", IFERROR( VLOOKUP($A23,'SUPPLIER DATA BASE'!$A$2:$F$936,6,0),"")) -> DIRECT | D23: =IF($A$3=" "," ", IFERROR( VLOOKUP($A23,'SUPPLIER DATA BASE'!$A$2:$G$936,4,0),"")) -> 15 | E23: =IF($A$3=" "," ", IFERROR( VLOOKUP($A23,'SUPPLIER DATA BASE'!$A$2:$H$936,5,0),"")) -> 5 | F23: IH/25-26/965 | G23: 46027 | H23: 93 | I23: 26019 | J23: C2D VENTURES -965.pdf | K23: - | L23: - | M23: =IF(G23="", "", (TODAY() - G23) & " Days") -> 161 Days | N23: =IF($A$3=" "," ", IFERROR( VLOOKUP($A23,'SUPPLIER DATA BASE'!$A$2:$O$936,11,0),"")) -> C2D VENTURES LLP | O23: =IF($A$3=" "," ", IFERROR( VLOOKUP($A23,'SUPPLIER DATA BASE'!$A$2:$O$936,12,0),"")) -> 50484840037 | P23: =IF($A$3=" "," ", IFERROR( VLOOKUP($A23,'SUPPLIER DATA BASE'!$A$2:$O$936,13,0),"")) -> IDIB000D600 | V23: =IF(G23="","", IF(AND(G23>=DATE(2024,4,1),G23<=DATE(2025,3,31)),"FY 24-25", IF(AND(G23>=DATE(2025,4,1),G23<=DATE(2026,3,31)),"FY 25-26",IF(AND(G23>=DATE(2026,4,1),G23<=DATE(2027,3,31)),"FY 26-27","")))) -> FY 25-26
A24: C2D VENTURES LLP | B24: =IF($A$3=" "," ", IFERROR( VLOOKUP($A24,'SUPPLIER DATA BASE'!$A$2:$M$936,3,0),"")) -> WELSPUN, VAN HEUSEN | C24: =IF($A$3=" "," ", IFERROR( VLOOKUP($A24,'SUPPLIER DATA BASE'!$A$2:$F$936,6,0),"")) -> DIRECT | D24: =IF($A$3=" "," ", IFERROR( VLOOKUP($A24,'SUPPLIER DATA BASE'!$A$2:$G$936,4,0),"")) -> 15 | E24: =IF($A$3=" "," ", IFERROR( VLOOKUP($A24,'SUPPLIER DATA BASE'!$A$2:$H$936,5,0),"")) -> 5 | F24: IH/25-26/964 | G24: 46027 | H24: 158 | I24: 89116 | J24: C2D VENTURES -964.pdf | K24: - | L24: - | M24: =IF(G24="", "", (TODAY() - G24) & " Days") -> 161 Days | N24: =IF($A$3=" "," ", IFERROR( VLOOKUP($A24,'SUPPLIER DATA BASE'!$A$2:$O$936,11,0),"")) -> C2D VENTURES LLP | O24: =IF($A$3=" "," ", IFERROR( VLOOKUP($A24,'SUPPLIER DATA BASE'!$A$2:$O$936,12,0),"")) -> 50484840037 | P24: =IF($A$3=" "," ", IFERROR( VLOOKUP($A24,'SUPPLIER DATA BASE'!$A$2:$O$936,13,0),"")) -> IDIB000D600 | V24: =IF(G24="","", IF(AND(G24>=DATE(2024,4,1),G24<=DATE(2025,3,31)),"FY 24-25", IF(AND(G24>=DATE(2025,4,1),G24<=DATE(2026,3,31)),"FY 25-26",IF(AND(G24>=DATE(2026,4,1),G24<=DATE(2027,3,31)),"FY 26-27","")))) -> FY 25-26
A25: DIL SE | B25: =IF($A$3=" "," ", IFERROR( VLOOKUP($A25,'SUPPLIER DATA BASE'!$A$2:$M$936,3,0),"")) -> - | C25: =IF($A$3=" "," ", IFERROR( VLOOKUP($A25,'SUPPLIER DATA BASE'!$A$2:$F$936,6,0),"")) -> - | D25: =IF($A$3=" "," ", IFERROR( VLOOKUP($A25,'SUPPLIER DATA BASE'!$A$2:$G$936,4,0),"")) -> - | E25: =IF($A$3=" "," ", IFERROR( VLOOKUP($A25,'SUPPLIER DATA BASE'!$A$2:$H$936,5,0),"")) -> - | F25: 2025-26/1316 | G25: 46028 | H25: 1 | I25: 3245 | J25: Dil se 1316.pdf | K25: - | L25: - | M25: =IF(G25="", "", (TODAY() - G25) & " Days") -> 160 Days | N25: =IF($A$3=" "," ", IFERROR( VLOOKUP($A25,'SUPPLIER DATA BASE'!$A$2:$O$936,11,0),"")) -> DIL SE | O25: =IF($A$3=" "," ", IFERROR( VLOOKUP($A25,'SUPPLIER DATA BASE'!$A$2:$O$936,12,0),"")) -> 11197610000574 | P25: =IF($A$3=" "," ", IFERROR( VLOOKUP($A25,'SUPPLIER DATA BASE'!$A$2:$O$936,13,0),"")) -> HDFC0001119 | V25: =IF(G25="","", IF(AND(G25>=DATE(2024,4,1),G25<=DATE(2025,3,31)),"FY 24-25", IF(AND(G25>=DATE(2025,4,1),G25<=DATE(2026,3,31)),"FY 25-26",IF(AND(G25>=DATE(2026,4,1),G25<=DATE(2027,3,31)),"FY 26-27","")))) -> FY 25-26
A26: SARAOGI SUPER SALES PVT LTD | B26: =IF($A$3=" "," ", IFERROR( VLOOKUP($A26,'SUPPLIER DATA BASE'!$A$2:$M$936,3,0),"")) -> - | C26: =IF($A$3=" "," ", IFERROR( VLOOKUP($A26,'SUPPLIER DATA BASE'!$A$2:$F$936,6,0),"")) -> - | D26: =IF($A$3=" "," ", IFERROR( VLOOKUP($A26,'SUPPLIER DATA BASE'!$A$2:$G$936,4,0),"")) -> - | E26: =IF($A$3=" "," ", IFERROR( VLOOKUP($A26,'SUPPLIER DATA BASE'!$A$2:$H$936,5,0),"")) -> - | F26: 25-26/BBS13151 | G26: 46030 | H26: 4 | I26: 7049 | J26: Saraogi Super Sales 13151.pdf | K26: - | L26: - | M26: =IF(G26="", "", (TODAY() - G26) & " Days") -> 158 Days | N26: =IF($A$3=" "," ", IFERROR( VLOOKUP($A26,'SUPPLIER DATA BASE'!$A$2:$O$936,11,0),"")) -> SARAOGI SUPER SALES PVT LTD | O26: =IF($A$3=" "," ", IFERROR( VLOOKUP($A26,'SUPPLIER DATA BASE'!$A$2:$O$936,12,0),"")) -> SASUSP011006 | P26: =IF($A$3=" "," ", IFERROR( VLOOKUP($A26,'SUPPLIER DATA BASE'!$A$2:$O$936,13,0),"")) -> ICIC0000106 | V26: =IF(G26="","", IF(AND(G26>=DATE(2024,4,1),G26<=DATE(2025,3,31)),"FY 24-25", IF(AND(G26>=DATE(2025,4,1),G26<=DATE(2026,3,31)),"FY 25-26",IF(AND(G26>=DATE(2026,4,1),G26<=DATE(2027,3,31)),"FY 26-27","")))) -> FY 25-26
A27: KIRAN CREATION | B27: =IF($A$3=" "," ", IFERROR( VLOOKUP($A27,'SUPPLIER DATA BASE'!$A$2:$M$936,3,0),"")) -> - | C27: =IF($A$3=" "," ", IFERROR( VLOOKUP($A27,'SUPPLIER DATA BASE'!$A$2:$F$936,6,0),"")) -> - | D27: =IF($A$3=" "," ", IFERROR( VLOOKUP($A27,'SUPPLIER DATA BASE'!$A$2:$G$936,4,0),"")) -> - | E27: =IF($A$3=" "," ", IFERROR( VLOOKUP($A27,'SUPPLIER DATA BASE'!$A$2:$H$936,5,0),"")) -> - | F27: SOCCRS25/770 | G27: 46032 | H27: 104 | I27: 11152 | J27: KIRAN CREATION -770.pdf | K27: - | L27: - | M27: =IF(G27="", "", (TODAY() - G27) & " Days") -> 156 Days | N27: =IF($A$3=" "," ", IFERROR( VLOOKUP($A27,'SUPPLIER DATA BASE'!$A$2:$O$936,11,0),"")) -> KIRAN CREATION | O27: =IF($A$3=" "," ", IFERROR( VLOOKUP($A27,'SUPPLIER DATA BASE'!$A$2:$O$936,12,0),"")) -> 50200007524171 | P27: =IF($A$3=" "," ", IFERROR( VLOOKUP($A27,'SUPPLIER DATA BASE'!$A$2:$O$936,13,0),"")) -> HDFC0000765 | V27: =IF(G27="","", IF(AND(G27>=DATE(2024,4,1),G27<=DATE(2025,3,31)),"FY 24-25", IF(AND(G27>=DATE(2025,4,1),G27<=DATE(2026,3,31)),"FY 25-26",IF(AND(G27>=DATE(2026,4,1),G27<=DATE(2027,3,31)),"FY 26-27","")))) -> FY 25-26
A28: C2D VENTURES LLP | B28: =IF($A$3=" "," ", IFERROR( VLOOKUP($A28,'SUPPLIER DATA BASE'!$A$2:$M$936,3,0),"")) -> WELSPUN, VAN HEUSEN | C28: =IF($A$3=" "," ", IFERROR( VLOOKUP($A28,'SUPPLIER DATA BASE'!$A$2:$F$936,6,0),"")) -> DIRECT | D28: =IF($A$3=" "," ", IFERROR( VLOOKUP($A28,'SUPPLIER DATA BASE'!$A$2:$G$936,4,0),"")) -> 15 | E28: =IF($A$3=" "," ", IFERROR( VLOOKUP($A28,'SUPPLIER DATA BASE'!$A$2:$H$936,5,0),"")) -> 5 | F28: IH/25-26/984 | G28: 46034 | H28: 60 | I28: 20604 | J28: C2D VENTURES -984.pdf | K28: - | L28: - | M28: =IF(G28="", "", (TODAY() - G28) & " Days") -> 154 Days | N28: =IF($A$3=" "," ", IFERROR( VLOOKUP($A28,'SUPPLIER DATA BASE'!$A$2:$O$936,11,0),"")) -> C2D VENTURES LLP | O28: =IF($A$3=" "," ", IFERROR( VLOOKUP($A28,'SUPPLIER DATA BASE'!$A$2:$O$936,12,0),"")) -> 50484840037 | P28: =IF($A$3=" "," ", IFERROR( VLOOKUP($A28,'SUPPLIER DATA BASE'!$A$2:$O$936,13,0),"")) -> IDIB000D600 | V28: =IF(G28="","", IF(AND(G28>=DATE(2024,4,1),G28<=DATE(2025,3,31)),"FY 24-25", IF(AND(G28>=DATE(2025,4,1),G28<=DATE(2026,3,31)),"FY 25-26",IF(AND(G28>=DATE(2026,4,1),G28<=DATE(2027,3,31)),"FY 26-27","")))) -> FY 25-26
A29: SHRIJEE ENTERPRISES | B29: =IF($A$3=" "," ", IFERROR( VLOOKUP($A29,'SUPPLIER DATA BASE'!$A$2:$M$936,3,0),"")) -> - | C29: =IF($A$3=" "," ", IFERROR( VLOOKUP($A29,'SUPPLIER DATA BASE'!$A$2:$F$936,6,0),"")) -> - | D29: =IF($A$3=" "," ", IFERROR( VLOOKUP($A29,'SUPPLIER DATA BASE'!$A$2:$G$936,4,0),"")) -> - | E29: =IF($A$3=" "," ", IFERROR( VLOOKUP($A29,'SUPPLIER DATA BASE'!$A$2:$H$936,5,0),"")) -> - | F29: THCRS25/430 | G29: 46034 | H29: 45 | I29: 27257 | J29: SHRIJEE ENTERPRISES -430.pdf | K29: - | L29: - | M29: =IF(G29="", "", (TODAY() - G29) & " Days") -> 154 Days | N29: =IF($A$3=" "," ", IFERROR( VLOOKUP($A29,'SUPPLIER DATA BASE'!$A$2:$O$936,11,0),"")) -> SHRIJEE ENTERPRISES | O29: =IF($A$3=" "," ", IFERROR( VLOOKUP($A29,'SUPPLIER DATA BASE'!$A$2:$O$936,12,0),"")) -> 31849543930 | P29: =IF($A$3=" "," ", IFERROR( VLOOKUP($A29,'SUPPLIER DATA BASE'!$A$2:$O$936,13,0),"")) -> SBIN0001521 | V29: =IF(G29="","", IF(AND(G29>=DATE(2024,4,1),G29<=DATE(2025,3,31)),"FY 24-25", IF(AND(G29>=DATE(2025,4,1),G29<=DATE(2026,3,31)),"FY 25-26",IF(AND(G29>=DATE(2026,4,1),G29<=DATE(2027,3,31)),"FY 26-27","")))) -> FY 25-26
A30: TATHASTU ENTERPRISE | B30: =IF($A$3=" "," ", IFERROR( VLOOKUP($A30,'SUPPLIER DATA BASE'!$A$2:$M$936,3,0),"")) -> - | C30: =IF($A$3=" "," ", IFERROR( VLOOKUP($A30,'SUPPLIER DATA BASE'!$A$2:$F$936,6,0),"")) -> SURYAM TEXTILE AGENCY | D30: =IF($A$3=" "," ", IFERROR( VLOOKUP($A30,'SUPPLIER DATA BASE'!$A$2:$G$936,4,0),"")) -> 50 | E30: =IF($A$3=" "," ", IFERROR( VLOOKUP($A30,'SUPPLIER DATA BASE'!$A$2:$H$936,5,0),"")) -> 10% IN BILL | F30: 8579 | G30: 46034 | H30: 25 | I30: 81731 | J30: Tathastu enterprise 8579.pdf | K30: - | L30: - | M30: =IF(G30="", "", (TODAY() - G30) & " Days") -> 154 Days | N30: =IF($A$3=" "," ", IFERROR( VLOOKUP($A30,'SUPPLIER DATA BASE'!$A$2:$O$936,11,0),"")) -> TATHASTU ENTERPRISE | O30: =IF($A$3=" "," ", IFERROR( VLOOKUP($A30,'SUPPLIER DATA BASE'!$A$2:$O$936,12,0),"")) -> 50200043443581 | P30: =IF($A$3=" "," ", IFERROR( VLOOKUP($A30,'SUPPLIER DATA BASE'!$A$2:$O$936,13,0),"")) -> HDFC0001704 | Q30: 81731 | R30: 46080 | V30: =IF(G30="","", IF(AND(G30>=DATE(2024,4,1),G30<=DATE(2025,3,31)),"FY 24-25", IF(AND(G30>=DATE(2025,4,1),G30<=DATE(2026,3,31)),"FY 25-26",IF(AND(G30>=DATE(2026,4,1),G30<=DATE(2027,3,31)),"FY 26-27","")))) -> FY 25-26
A31: JAIN ADISHWAR HOSIERY WORKS LLP | B31: =IF($A$3=" "," ", IFERROR( VLOOKUP($A31,'SUPPLIER DATA BASE'!$A$2:$M$936,3,0),"")) -> - | C31: =IF($A$3=" "," ", IFERROR( VLOOKUP($A31,'SUPPLIER DATA BASE'!$A$2:$F$936,6,0),"")) -> - | D31: =IF($A$3=" "," ", IFERROR( VLOOKUP($A31,'SUPPLIER DATA BASE'!$A$2:$G$936,4,0),"")) -> - | E31: =IF($A$3=" "," ", IFERROR( VLOOKUP($A31,'SUPPLIER DATA BASE'!$A$2:$H$936,5,0),"")) -> - | F31: J/25-26/10186 | G31: 46035 | H31: 72 | I31: 208983 | J31: JAIN ADISHWAR -10186.pdf | K31: - | L31: - | M31: =IF(G31="", "", (TODAY() - G31) & " Days") -> 153 Days | N31: =IF($A$3=" "," ", IFERROR( VLOOKUP($A31,'SUPPLIER DATA BASE'!$A$2:$O$936,11,0),"")) -> JAIN ADISHWAR HOSIERY WORKS LLP | O31: =IF($A$3=" "," ", IFERROR( VLOOKUP($A31,'SUPPLIER DATA BASE'!$A$2:$O$936,12,0),"")) -> 99917644444444 | P31: =IF($A$3=" "," ", IFERROR( VLOOKUP($A31,'SUPPLIER DATA BASE'!$A$2:$O$936,13,0),"")) -> HDFC0002063 | V31: =IF(G31="","", IF(AND(G31>=DATE(2024,4,1),G31<=DATE(2025,3,31)),"FY 24-25", IF(AND(G31>=DATE(2025,4,1),G31<=DATE(2026,3,31)),"FY 25-26",IF(AND(G31>=DATE(2026,4,1),G31<=DATE(2027,3,31)),"FY 26-27","")))) -> FY 25-26
A32: SHRITHIK DESIGNER LLP | B32: =IF($A$3=" "," ", IFERROR( VLOOKUP($A32,'SUPPLIER DATA BASE'!$A$2:$M$936,3,0),"")) -> - | C32: =IF($A$3=" "," ", IFERROR( VLOOKUP($A32,'SUPPLIER DATA BASE'!$A$2:$F$936,6,0),"")) -> SURYAM TEXTILE AGENCY | D32: =IF($A$3=" "," ", IFERROR( VLOOKUP($A32,'SUPPLIER DATA BASE'!$A$2:$G$936,4,0),"")) -> NO | E32: =IF($A$3=" "," ", IFERROR( VLOOKUP($A32,'SUPPLIER DATA BASE'!$A$2:$H$936,5,0),"")) -> - | F32: 19541 | G32: 46035 | H32: 62 | I32: 54167 | J32: SHRITHIK DESIGNER -1953.pdf | K32: - | L32: - | M32: =IF(G32="", "", (TODAY() - G32) & " Days") -> 153 Days | N32: =IF($A$3=" "," ", IFERROR( VLOOKUP($A32,'SUPPLIER DATA BASE'!$A$2:$O$936,11,0),"")) -> SHRITHIK DESIGNER LLP | O32: =IF($A$3=" "," ", IFERROR( VLOOKUP($A32,'SUPPLIER DATA BASE'!$A$2:$O$936,12,0),"")) -> 339805000598 | P32: =IF($A$3=" "," ", IFERROR( VLOOKUP($A32,'SUPPLIER DATA BASE'!$A$2:$O$936,13,0),"")) -> ICIC0003398 | Q32: 54167 | R32: 46131 | V32: =IF(G32="","", IF(AND(G32>=DATE(2024,4,1),G32<=DATE(2025,3,31)),"FY 24-25", IF(AND(G32>=DATE(2025,4,1),G32<=DATE(2026,3,31)),"FY 25-26",IF(AND(G32>=DATE(2026,4,1),G32<=DATE(2027,3,31)),"FY 26-27","")))) -> FY 25-26
A33: UNNATI CREATION | B33: =IF($A$3=" "," ", IFERROR( VLOOKUP($A33,'SUPPLIER DATA BASE'!$A$2:$M$936,3,0),"")) -> - | C33: =IF($A$3=" "," ", IFERROR( VLOOKUP($A33,'SUPPLIER DATA BASE'!$A$2:$F$936,6,0),"")) -> SURYAM TEXTILE AGENCY | D33: =IF($A$3=" "," ", IFERROR( VLOOKUP($A33,'SUPPLIER DATA BASE'!$A$2:$G$936,4,0),"")) -> 60 | E33: =IF($A$3=" "," ", IFERROR( VLOOKUP($A33,'SUPPLIER DATA BASE'!$A$2:$H$936,5,0),"")) -> 5% IN BILL | F33: 416/PF | G33: 46035 | H33: 29 | I33: 51401 | J33: Unnati creation 416.pdf | K33: - | L33: - | M33: =IF(G33="", "", (TODAY() - G33) & " Days") -> 153 Days | N33: =IF($A$3=" "," ", IFERROR( VLOOKUP($A33,'SUPPLIER DATA BASE'!$A$2:$O$936,11,0),"")) -> UNNATI CREATION | O33: =IF($A$3=" "," ", IFERROR( VLOOKUP($A33,'SUPPLIER DATA BASE'!$A$2:$O$936,12,0),"")) -> 99992001015861 | P33: =IF($A$3=" "," ", IFERROR( VLOOKUP($A33,'SUPPLIER DATA BASE'!$A$2:$O$936,13,0),"")) -> GSCB0ASCB02 | Q33: 51401 | R33: 46080 | V33: =IF(G33="","", IF(AND(G33>=DATE(2024,4,1),G33<=DATE(2025,3,31)),"FY 24-25", IF(AND(G33>=DATE(2025,4,1),G33<=DATE(2026,3,31)),"FY 25-26",IF(AND(G33>=DATE(2026,4,1),G33<=DATE(2027,3,31)),"FY 26-27","")))) -> FY 25-26
A34: AS TEXTILE | B34: =IF($A$3=" "," ", IFERROR( VLOOKUP($A34,'SUPPLIER DATA BASE'!$A$2:$M$936,3,0),"")) -> - | C34: =IF($A$3=" "," ", IFERROR( VLOOKUP($A34,'SUPPLIER DATA BASE'!$A$2:$F$936,6,0),"")) -> SURYAM TEXTILE AGENCY | D34: =IF($A$3=" "," ", IFERROR( VLOOKUP($A34,'SUPPLIER DATA BASE'!$A$2:$G$936,4,0),"")) -> 30 | E34: =IF($A$3=" "," ", IFERROR( VLOOKUP($A34,'SUPPLIER DATA BASE'!$A$2:$H$936,5,0),"")) -> 0.09 | F34: 131 | G34: 46035 | H34: 2 | I34: 17388 | J34: A S Textile 131.pdf | K34: - | L34: - | M34: =IF(G34="", "", (TODAY() - G34) & " Days") -> 153 Days | N34: =IF($A$3=" "," ", IFERROR( VLOOKUP($A34,'SUPPLIER DATA BASE'!$A$2:$O$936,11,0),"")) -> AS TEXTILE | O34: =IF($A$3=" "," ", IFERROR( VLOOKUP($A34,'SUPPLIER DATA BASE'!$A$2:$O$936,12,0),"")) -> 50200012846193 | P34: =IF($A$3=" "," ", IFERROR( VLOOKUP($A34,'SUPPLIER DATA BASE'!$A$2:$O$936,13,0),"")) -> HDFC0001249 | Q34: 17388 | R34: 46064 | V34: =IF(G34="","", IF(AND(G34>=DATE(2024,4,1),G34<=DATE(2025,3,31)),"FY 24-25", IF(AND(G34>=DATE(2025,4,1),G34<=DATE(2026,3,31)),"FY 25-26",IF(AND(G34>=DATE(2026,4,1),G34<=DATE(2027,3,31)),"FY 26-27","")))) -> FY 25-26
